<?xml version="1.0"?>
<robot name="custom_bot">
    <link name="base_link">
        <visual>
            <geometry>
                <box size="0.6 0.3 0.1"/>
            </geometry>
            <material name="red">
                <color rgba="1 0.0 0.0 1"/>
            </material>
        </visual>
    </link>
    <link name="front_caster_of_wheel">
        <visual>
            <geometry>
                <box size="0.1 0.1 0.1"/>
            </geometry>
            <material name="green">
                <color rgba="0.0 0.1 0.0 1"/>   
            </material>
        </visual>
    </link>
    <joint name="front_caster_of_wheel_joint" type="continuous">
        <axis xyz="0.0 0.0 1"/> 
        <parent link="base_link"/>
        <child link="front_caster_of_wheel"/>
        <origin xyz="0.3 0.0 0.0" rpy="0.0 0.0 0.0"/>
     </joint>

     <link name="front_wheel">
        <visual>
            <geometry>
                <cylinder radius="0.035" length="0.05"/>
            </geometry>
            <material name="black">
                
            </material>

        </visual>
    </link>
    <joint name="front_wheel_joint" type="continuous">
            <axis xyz="0.0 0.0 1"/>
            <parent link="front_caster_of_wheel"/>
            <child link="front_wheel"/>
            <origin xyz="0.05 0.0 -0.05" rpy="-1.5708 0.0 0.0"/>
            
    </joint>

    <link name="right_wheel">
        <visual>
            <geometry>
                <cylinder radius="0.035" length="0.05"/>
            </geometry>
            <material name="black">
                <color rgba="0.0 0.0 0.0 1"/>
            </material>

        </visual>
    </link>
    <joint name="right_wheel_joint" type="continuous">
        <axis xyz="0.0 0.0 1"/>
        <parent link="base_link"/>
        <child link="right_wheel"/>
        <origin xyz="-0.2825 -0.125 -0.05" rpy="-1.5708 0.0 0.0"/>
        
    </joint>
    <link name="left_wheel">
        <visual>
            <geometry>
                <cylinder radius="0.035" length="0.05"/>
            </geometry>
            <material name="black">
                <color rgba="0.0 0.0 0.0 1"/>
            </material>

        </visual>

    </link>

    <joint name="left_wheel_joint" type="continuous">
        <axis xyz="0.0 0.0 1"/>
        <parent link="base_link"/>
        <child link="left_wheel"/>
        <origin xyz="-0.2825 0.125 -0.05" rpy="-1.5708 0.0 0.0"/>
        
    </joint> -->
</robot>
